Workbook

Sheet Одит на цитиранията
A1: Вид дупка | B1: Абзац | C1: Източник(ци) | D1: Изречение | E1: Лист | F1: Ред | G1: Статус на реда | H1: Пакет (по източник) | I1: Решено на
A2: БЕЗ РЕД | B2: 33 | C2: [11] | D2: Консенсусната дефиниция, изведена чрез международно експертно проучване, определя електронното обучение като подход към преподаването и ученето, който | E2: — | F2: — | G2: — | H2: [11]
A3: БЕЗ РЕД | B3: 34 | C3: [11] | D3: В настоящата разработка трите понятия се разграничават така: електронното обучение е подходът към преподаването и ученето, който представя прилагания | E3: — | F3: — | G3: — | H3: [11]
A4: БЕЗ РЕД | B4: 34 | C4: [37] | D4: Clark и Mayer определят електронното обучение като обучение, доставяно чрез цифрово устройство и предназначено да подпомага ученето, като изрично отде | E4: — | F4: — | G4: — | H4: [37]
A5: БЕЗ РЕД | B5: 37 | C5: [52] | D5: Стандартът за метаданни на учебни обекти отразява това, като включва контекста на употреба сред описателните характеристики на учебния обект [52]. | E5: — | F5: — | G5: — | H5: [52]
A6: БЕЗ РЕД | B6: 40 | C6: [52] | D6: Схемата за метаданни на учебни обекти по стандарта IEEE 1484.12.1 определя структура от девет категории описателни характеристики от първо ниво, сред | E6: — | F6: — | G6: — | H6: [52]
A7: БЕЗ РЕД | B7: 42 | C7: [24] | D7: Емпиричното изследване на остарелите отговори в най-голямата платформа за програмистки въпроси установява, че над половината от тях (58,4 на сто) са б | E7: — | F7: — | G7: — | H7: [24]
A8: БЕЗ РЕД | B8: 43 | C8: [49] | D8: Ръководството на 1EdTech за съдържание, създадено с генеративен изкуствен интелект, степенува този признак в пет равнища - от съдържание, създадено от | E8: — | F8: — | G8: — | H8: [49]
A9: БЕЗ РЕД | B9: 56 | C9: [48] | D9: Експерименталното изследване на разгърнатата обратна връзка уточнява това: подробното обяснение подобрява възприемането на обратната връзка и преноса | E9: — | F9: — | G9: — | H9: [48]
A10: БЕЗ РЕД | B10: 57 | C10: [48] | D10: Разгърнатата обратна връзка се определя като допълнителна инструктивна информация към верния отговор - обяснения, насоки и стъпки за решаване [48]. | E10: — | F10: — | G10: — | H10: [48]
A11: БЕЗ РЕД | B11: 62 | C11: [46] | D11: Изследванията върху приложението на генеративния изкуствен интелект в образованието нарастват рязко след пускането на ChatGPT през ноември 2022 г.: би | E11: — | F11: — | G11: — | H11: [46]
A12: БЕЗ РЕД | B12: 63 | C12: [44] | D12: Първата е начинът на обработка на текста: моделът не работи с думи, а с по-малки единици, наречени токени, и на всяка стъпка избира следващата единица | E12: — | F12: — | G12: — | H12: [44]
A13: БЕЗ РЕД | B13: 63 | C13: [32] | D13: Емпиричните изследвания показват, че подадената информация не се използва еднакво надеждно по цялата си дължина: представянето се влошава осезаемо, ко | E13: — | F13: — | G13: — | H13: [32]
... A35: БЕЗ РЕД | B35: 221 | C35: [10, 16] | D35: Положението е свързано с документираната неравномерност на езиковото покритие в изследванията и в обучителните данни [16], [10]. | E35: — | F35: — | G35: — | H35: [10, 16]
A36: ИЗВАДКА ПОД 2 ИЗРЕЧЕНИЯ | B36: 35 | C36: [12] | D36: Значимостта на работата с дигитални ресурси за съвременния преподавател е призната и на рамково равнище: в евр | E36: Ниво 2 Твърдения | F36: 3 | G36: — | H36: [12]
A37: ИЗВАДКА ПОД 2 ИЗРЕЧЕНИЯ | B37: 44 | C37: [49] | D37: При най-високото равнище от същата скала обаче съдържанието се създава и публикува с минимален или никакъв чов | E37: Ниво 2 Твърдения | F37: 68 | G37: — | H37: [49]
A38: ИЗВАДКА ПОД 2 ИЗРЕЧЕНИЯ | B38: 55 | C38: [12] | D38: В европейската рамка DigCompEdu изборът и създаването на дигитални ресурси изрично се обвързват с отчитането н | E38: Ниво 2 Твърдения | F38: 14 | G38: — | H38: [12]
A39: ИЗВАДКА ПОД 2 ИЗРЕЧЕНИЯ | B39: 67 | C39: [27] | D39: Систематизациите на халюцинациите достигат до същия извод - надеждното им отстраняване на равнище модел остава | E39: Ниво 2 Твърдения | F39: 21 | G39: — | H39: [27]
A40: ИЗВАДКА ПОД 2 ИЗРЕЧЕНИЯ | B40: 77 | C40: [16] | D40: Първото и най-разпространено равнище е подпомогнатото създаване: преподавателят взаимодейства с инструмента чр | E40: Ниво 2 Твърдения | F40: 25 | G40: — | H40: [16]
A41: ИЗВАДКА ПОД 2 ИЗРЕЧЕНИЯ | B41: 78 | C41: [15] | D41: Рамката GAIDE предлага систематизиран процес за използване на генеративни инструменти при разработване на курс | E41: Ниво 2 Твърдения | F41: 26 | G41: — | H41: [15]
A42: ИЗВАДКА ПОД 2 ИЗРЕЧЕНИЯ | B42: 78 | C42: [14] | D42: По-широк поглед дава интегративният преглед на Chai и колектив върху 71 публикации, който картографира приложе | E42: Ниво 2 Твърдения | F42: 27 | G42: — | H42: [14]
A43: ИЗВАДКА ПОД 2 ИЗРЕЧЕНИЯ | B43: 79 | C43: [3] | D43: Показателен пример от българската практика е концептуалният дизайн на платформа за обучение по дентална анатом | E43: Ниво 2 Твърдения | F43: 28 | G43: — | H43: [3]
A44: ИЗВАДКА ПОД 2 ИЗРЕЧЕНИЯ | B44: 81 | C44: [8] | D44: Прегледът на около 130 източника за приложението на изкуствения интелект в обучението по програмиране обобщава | E44: Ниво 2 Твърдения | F44: 31 | G44: — | H44: [8]
A45: ИЗВАДКА ПОД 2 ИЗРЕЧЕНИЯ | B45: 81 | C45: [6] | D45: Публикувано описание на инструментален работен процес в българско висше училище посочва значително съкращаване | E45: Ниво 2 Твърдения | F45: 32 | G45: — | H45: [6]
A46: ИЗВАДКА ПОД 2 ИЗРЕЧЕНИЯ | B46: 82 | C46: [2] | D46: Разработена в морско висше училище система обработва над 656 000 знака учебен текст на български и английски е | E46: Ниво 2 Твърдения | F46: 33 | G46: — | H46: [2]
A47: ИЗВАДКА ПОД 2 ИЗРЕЧЕНИЯ | B47: 83 | C47: [6] | D47: Практическо ръководство за преподаватели извежда набор от правила - определяне на роля, предоставяне на контек | E47: Ниво 2 Твърдения | F47: 34 | G47: — | H47: [6]
... A86: НЕПОТВЪРДЕН СТАТУС | B86: 164 | C86: [19] | D86: Систематичният преглед на 93 изследвания в тази област показва, че още преди големите език | E86: Гл.2–3 Ниво 2 | F86: 14 | G86: Частично потвърдено | H86: [19]

Sheet Метод
B1: План за потвърждаване на цитираното от всички източници
B2: НИП „Александър Гръмов“ — Първа глава, 36 източника, 64 цитирани твърдения
B4: Защо е нужно | C4: Първа глава има 36 източника и 64 места, където конкретно твърдение е обвързано с източник. Част от записите носят признаци на риск: запис без автор с arXiv номер от 2026 г., два записа от конференции с 2026 г., един непрофилен източник (документация на Angular), един запис без DOI. Отделно 15 твърдения съдържат точни числа (проценти, брой публикации, брой стандарти), които или се потвърждават дословно, или трябва да отпаднат.
B6: Двустепенен принцип | C6: Ниво 1 проверява дали източникът съществува и дали библиографският запис е верен. Ниво 2 проверява дали конкретното твърдение наистина се съдържа в източника и на посоченото място. Източник може да мине Ниво 1 и да се провали на Ниво 2 — това е по-опасната грешка, защото не се вижда при повърхностен преглед.
B8: Ред на работа | C8: 1) Ниво 1 за всички 36 записа. 2) Ниво 2 за твърденията с приоритет „Критичен“ (числа и точни структури). 3) Ниво 2 за „Висок“. 4) Ниво 2 за останалите. 5) Отстраняване на находките в текста. 6) Финален контрол по листа „Обобщение“.
B10: Критерий „Потвърдено“ | C10: Отворен е самият източник (не абстракт, не вторично цитиране), намерено е мястото, което носи твърдението, и формулировката в текста не е по-силна от формулировката в източника. Записва се страница/раздел в колона „Намерено на“.
B12: Критерий „Частично“ | C12: Твърдението се съдържа, но обхватът, числото или категоричността се разминават. Изисква преформулиране в текста — не отпадане на източника.
B14: Специално правило: числа | C14: Всяко число се проследява до първоизточника. Ако източникът сам цитира числото от другаде (напр. ред 61), цитира се първоизточникът или се пише „по данни, цитирани в [X]“.
B16: Специално правило: локатори | C16: Локаторите [30, гл. 1/4/9/12/13/21], [27, с. 44–45], [12, обл. 2] се проверяват срещу точното издание. Номерата на глави се менят между изданията — това е най-честият източник на невярна препратка при преизползван локатор от по-старо издание.
B18: Специално правило: приписване | C18: За обобщаващи изречения („систематичните прегледи показват…“) се проверява дали изводът е на източника или е авторски синтез. Ако е авторски — цитатът се премества или се преформулира. Засегнати редове: 8, 23, 45, 46.
B20: Инструменти | C20: DOI резолвер (doi.org), Crossref, arXiv, IEEE Xplore, Google Scholar, EUR-Lex за [31], сайтовете на UNESCO, Quality Matters и IEEE SA. За българските сборници [1–6, 8, 9] — сборникът на конференцията в Русе (PDF/ISBN) или директна връзка с авторите; онлайн проверка вероятно няма да е достатъчна.
B22: Оценка на обема | C22: Ниво 1: около 3–4 часа за 36 записа. Ниво 2: около 8–12 часа, като тежестта е в 15-те критични реда и в достъпа до платените издания. Реалистичен срок при 2–3 часа дневно — 5 работни дни.
B24: Как се попълва | C24: Работи се само в колоните със светложълт фон: „Статус“, „Намерено на“, „Бележка/действие“, „Проверил“, „Дата“. Останалите колони са входни данни, извлечени от документа. Листът „Обобщение“ се преизчислява сам.
B28: Пилот humanize (28.08.2026) | C28: Раздел 1.5 беше пренаписан с humanizer и отхвърлен. Цитатите и числата се запазиха, но обемът се сви с 39 %, всичките 12 цитирани изречения бяха променени, седем конкретни детайла отпаднаха („трите оценъчни оси“, „от всички образователни степени“, „между отделни заявки“ и др.), периодът 2007–2018 излезе от изречението със своя цитат, описателно твърдение за литературата стана нормативно предписание с чужд цитат зад него, и се появи неподкрепена причинно-следствена връзка („генеративните инструменти наследяват този дефицит“). РЕШЕНИЕ: текстът НЕ се пренаписва. Инструментът се ползва само като детектор. Проверката тече срещу оригиналния текст.
B30: Ревизия 31.08.2026 — покритие на Ниво 1
B31: Листовете „Ниво 1 Източници“ и „Гл.2–3 Ниво 1“ използват стара номерация (42, съотв. междинен списък) и не покриваха целия текущ списък: 10 източника — [11], [22], [24], [32], [38], [44], [45], [46], [48], [49] — нямаха нито един ред за Ниво 1. Листът „Ниво 1 — всички 53“ е новият меродавен: съдържа всеки от 53-те записа по текущата номерация, статуса му и препратка към предишния ред. Старите листове се запазват само като история.
B33: Одит 01.09.2026 — определение за „готово“
B34: Скриптът proverka_citirane.py изброява всяко изречение с цитат и проверява дали има ред с ДОСЛОВНА извадка — от 01.09.2026 изискването е ПОНЕ ДВЕ ИЗРЕЧЕНИЯ в кавички, не отделни думи. При това изискване: 115 изречения с цитат, 30 покрити, 85 дупки — вж. листа „Одит на цитиранията“. Работата не е готова, докато скриптът не върне „дупки: 0“. Правилата са в Protokol_citirane.md.

Sheet Ниво 1 Източници
A1: № | B1: Нов № | C1: Източник (кратко) | D1: Тип | E1: Год. | F1: Идентификатор / локация | G1: Локален файл (extracted_md) | H1: Линк, използван при проверката | I1: Как се проверява | J1: Риск | K1: Основание за риска | L1: Брой твърдения | M1: Статус | N1: Намерено / DOI потвърден | O1: Бележка / действие | P1: Проверил | Q1: Дата
A2: 1 | B2: 1 | C2: А. Захариев — ИИ в ОНС „доктор“: дигитализация, регулация, кредитна акселерация | D2: Доклад в сборник (BG) | E2: 2026 | F2: Сб. „Дигитална трансформация на образованието“, Русе, с. 15–23 | G2: 2026_p-2.md | H2: https://www.conf-dte.bg/docs/2026/p-2.pdf | I2: Сборник на конференцията (PDF/ISBN); при липса — контакт с организатора или автора | J2: Среден | K2: Сборник от 2026 г.; онлайн наличност несигурна. Твърдение с нормативна конкретика (ред 49). | L2: =COUNTIF('Ниво 2 Твърдения'!$C$2:$C$65,"*["&A2&"]*") | M2: Потвърдено | N2: 2026_p-2.pdf, печ. стр. 15–23 | O2: Заглавие, автор (Андрей Захариев) и страници съвпадат. | P2: Claude (авт.) | Q2: 28.08.2026
A3: 2 | B3: 2 | C3: Д. Димитранов, Г. Димитров — ИИ за автоматизирано създаване на бази с тестови въпроси | D3: Доклад в сборник (BG) | E3: 2026 | F3: Същият сборник, с. 576–580 | G3: 2026_p-100.md | H3: https://www.conf-dte.bg/docs/2026/p-100.pdf | I3: Сборник; проверка на числата 656 000 знака / 553 въпроса | J3: Висок | K3: Носи три точни числа (ред 32) в доклад от 5 страници. | L3: =COUNTIF('Ниво 2 Твърдения'!$C$2:$C$65,"*["&A3&"]*") | M3: Потвърдено | N3: 2026_p-100.pdf, печ. стр. 576–580 | O3: Дилян Димитранов, Георги Димитров — съвпада. | P3: Claude (авт.) | Q3: 28.08.2026
A4: 3 | B4: 3 | C4: Е. Даскалова и кол. — платформа за обучение по дентална анатомия | D4: Доклад в сборник (BG) | E4: 2026 | F4: Същият сборник, с. 554–558 | G4: 2026_p-96.md | H4: https://www.conf-dte.bg/docs/2026/p-96.pdf | I4: Сборник; проверка на списъка от петима автори | J4: Среден | K4: Пет автора и точни страници — типично място за грешка при пренос. | L4: =COUNTIF('Ниво 2 Твърдения'!$C$2:$C$65,"*["&A4&"]*") | M4: Потвърдено | N4: 2026_p-96.pdf, печ. стр. 554–558 | O4: Петимата автори съвпадат, вкл. Весела Стефанова. | P4: Claude (авт.) | Q4: 28.08.2026
A5: 4 | B5: 4 | C5: М. Дамесова — генеративен ИИ и дигитален storytelling | D5: Доклад в сборник (BG) | E5: 2026 | F5: Същият сборник, с. 717–721 | G5: 2026_p-124.md | H5: https://www.conf-dte.bg/docs/2026/p-124.pdf | I5: Сборник | J5: Среден | K5: Достъп. | L5: =COUNTIF('Ниво 2 Твърдения'!$C$2:$C$65,"*["&A5&"]*") | M5: Потвърдено | N5: 2026_p-124.pdf, печ. стр. 717–721 | O5: Милена Дамесова — съвпада. | P5: Claude (авт.) | Q5: 28.08.2026
A6: 5 | B6: 5 | C6: М. Левунлиева — ИИ в образованието, перспективата на педагога | D6: Доклад в сборник (BG) | E6: 2026 | F6: Същият сборник, с. 605–610 | G6: 2026_p-106.md | H6: https://www.conf-dte.bg/docs/2026/p-106.pdf | I6: Сборник; проверка на извадката от 68 специалисти и на „трите оценъчни оси“ | J6: Висок | K6: Емпирично твърдение с число и методика (ред 41). | L6: =COUNTIF('Ниво 2 Твърдения'!$C$2:$C$65,"*["&A6&"]*") | M6: Потвърдено | N6: 2026_p-106.pdf, печ. стр. 605–610 | O6: Милена Левунлиева — съвпада. | P6: Claude (авт.) | Q6: 28.08.2026
A7: 6 | B7: 6 | C7: М. Маркова — ИИ за ускорено учене: практически инструменти | D7: Доклад в сборник (BG) | E7: 2026 | F7: Същият сборник, с. 541–546 | G7: 2026_p-94.md | H7: https://www.conf-dte.bg/docs/2026/p-94.pdf | I7: Сборник; проверка на диапазона 75–90 % | J7: Критичен | K7: Единственият източник за количествено твърдение, представено в текста в мн. ч. („публикувани описания“) — ред 31. | L7: =COUNTIF('Ниво 2 Твърдения'!$C$2:$C$65,"*["&A7&"]*") | M7: Потвърдено | N7: 2026_p-94.pdf, печ. стр. 541–546 | O7: Мая Маркова — записът е верен. ВНИМАНИЕ: твърдението в ред 31 на Ниво 2 не се потвърждава. | P7: Claude (авт.) | Q7: 28.08.2026
A8: 7 | B8: 7 | C8: С. Гафтанджиева, Р. Донева — Генеративен ИИ в образованието | D8: Списание (BG) | E8: 2025 | F8: doi: 10.53656/ped2025-9.04; Педагогика, т. 97, кн. 9, с. 1284–1297 | G8: generativen-...-reseniya.md | H8: https://journals.azbuki.bg/pedagogy/generativen-izkustven-intelekt-v-obrazovanieto-problemi-i-reseniya/view | I8: DOI резолвер; проверка на вторично цитираното число „една шеста“ | J8: Критичен | K8: Числото е цитирано от друг източник — трябва проследяване до първоизточника (ред 61). | L8: =COUNTIF('Ниво 2 Твърдения'!$C$2:$C$65,"*["&A8&"]*") | M8: Потвърдено | N8: печ. стр. 1284–1297; doi 10.53656/ped2025-9.04 | O8: Педагогика, т. 97, кн. 9, 2025 — съвпада. | P8: Claude (авт.) | Q8: 28.08.2026
A9: 8 | B9: 8 | C9: Ц. Василев — ИИ в обучението: студент и преподавател | D9: Доклад в сборник (BG) | E9: 2026 | F9: Същият сборник, с. 24–32 | G9: 2026_p-3.md | H9: https://www.conf-dte.bg/docs/2026/p-3.pdf | I9: Сборник; проверка дали докладът наистина прави преглед на ~130 източника | J9: Висок | K9: Обзор на 130 източника в доклад от 9 страници е необичайно — ред 30. | L9: =COUNTIF('Ниво 2 Твърдения'!$C$2:$C$65,"*["&A9&"]*") | M9: Потвърдено | N9: 2026_p-3.pdf, печ. стр. 24–32 | O9: Цветомир Василев — съвпада. | P9: Claude (авт.) | Q9: 28.08.2026
A10: 9 | B10: 9 | C10: Ц. Дуцова — аспекти на приложението на ИИ в образованието | D10: Доклад в сборник (BG) | E10: 2025 | F10: Трета конференция, Русе, с. 472–478 | G10: 2025_p-84.md | H10: https://www.conf-dte.bg/docs/2025/p-84.pdf | I10: Сборник | J10: Среден | K10: Достъп. | L10: =COUNTIF('Ниво 2 Твърдения'!$C$2:$C$65,"*["&A10&"]*") | M10: Потвърдено | N10: 2025_p-84.pdf, печ. стр. 472–478 | O10: Цветанка Дуцова, Трета конференция 2025 — съвпада. | P10: Claude (авт.) | Q10: 28.08.2026
A11: 10 | B11: 10 | C11: „Challenges and recommendations for LLMs-as-a-judge in multilingual settings…“ | D11: Препринт | E11: 2026 | F11: arXiv:2607.02235 | G11: https://arxiv.org/html/2607.02235v1 | H11: https://arxiv.org/html/2607.02235v1 | I11: arxiv.org/abs/2607.02235 — първо съществуване, после авторство | J11: Критичен | K11: Записът е без автори — единственият такъв в списъка. Носи две числа (над 650 публикации, 33 изследвания) и подпира извод в „Изводи от първа глава“ (редове 60, 64). | L11: =COUNTIF('Ниво 2 Твърдения'!$C$2:$C$65,"*["&A11&"]*") | M11: Потвърдено | N11: arXiv:2607.02235 — съществува | O11: Заглавието съвпада. Автори: A. S. Doğruöz, X. Liao, V. Blaschke, J. Prange, S. Li, D. I. Adelani и др. ДЕЙСТВИЕ: добави авторите — запис без автор е формално некоректен по IEEE. Числата 650/33 се потвърждават. || НАНЕСЕНО В НИП 28.08: добави „A. S. Doğruöz et al.“ пред заглавието. | P11: Claude (авт.) | Q11: 28.08.2026
A12: 11 | B12: 23 | C12: Angular Team — Angular versioning and releases | D12: Вендорска документация | E12: 2026 | F12: https://angular.dev/reference/releases | G12: https://angular.dev/reference/releases#release-frequency | H12: https://angular.dev/reference/releases#release-frequency | I12: Отваряне на страницата; проверка дали подкрепя общото твърдение | J12: Критичен | K12: Непрофилен източник в педагогически труд; използван за обобщение за „широко използвани софтуерни рамки“ въз основа на една рамка (ред 7). Обмисли замяна или отпадане. | L12: =COUNTIF('Ниво 2 Твърдения'!$C$2:$C$65,"*["&A12&"]*") | M12: Потвърдено | N12: angular.dev/reference/releases || ОТПАДА. Заменя се с Zhang и кол. (2019/2021), „An Empirical Study of Obsolete Answers on Stack Overflow“, IEEE Transactions on Software Engineering, 47(4), 850–862, doi 10.1109/TSE.2019.2906315. Рецензирано изследване вместо вендорска документация. | O12: Страницата съществува, но казва ЕДНА мажорна версия на 12 месеца и 24 месеца поддръжка (12 активна + 12 LTS). Виж ред 7 на Ниво 2. || НАНЕСЕНО В НИП 28.08: връзката става https://angular.dev/reference/releases#release-frequency — разделът наистина доказва една мажорна версия годишно, но само за Angular. | P12: Claude (авт.) | Q12: 28.08.2026
A13: 12 | B13: 13 | C13: C. Redecker — DigCompEdu | D13: Рамков документ (ЕС) | E13: 2017 | F13: JRC107466, Publications Office of the EU | G13: https://joint-research-centre.ec.europa.eu/digcompedu_en | H13: https://joint-research-centre.ec.europa.eu/digcompedu_en | I13: Свободно достъпен PDF на JRC | J13: Нисък | K13: Стабилен източник; проверява се само номерацията на област 2. | L13: =COUNTIF('Ниво 2 Твърдения'!$C$2:$C$65,"*["&A13&"]*") | M13: Потвърдено | N13: JRC107466, Publications Office of the EU, 2017 | O13: Redecker, ред. Punie — съвпада. | P13: Claude (авт.) | Q13: 28.08.2026
... A21: 20 | B21: 22 | C21: H. Yao et al. — Instructional Agents | D21: Конференция | E21: 2026 | F21: Proc. EACL 2026, т. 1, с. 4087–4109 | G21: https://aclanthology.org/2026.eacl-long.191/ | H21: https://aclanthology.org/2026.eacl-long.191/ | I21: ACL Anthology | J21: Висок | K21: Публикация от 2026 г. с точни страници — потвърди, че томът е излязъл и че страниците съвпадат. | L21: =COUNTIF('Ниво 2 Твърдения'!$C$2:$C$65,"*["&A21&"]*") | M21: Потвърдено | N21: aclanthology.org/2026.eacl-long.191, т. 1, с. 4087–4109 | O21: Съществува. Автори H. Yao, W. Xu, J. Turnau, N. Kellam, H. Wei; страниците съвпадат. DOI: 10.18653/v1/2026.eacl-long.191 — ДЕЙСТВИЕ: добави го. || НАНЕСЕНО В НИП 28.08: добави doi: 10.18653/v1/2026.eacl-long.191. | P21: Claude (авт.) | Q21: 28.08.2026
A22: 21 | B22: ОТПАДА | C22: I. du Preez, L. Jacobs — принципи за онлайн учебни материали | D22: Списание | E22: 2025 | F22: doi: 10.1080/10494820.2025.2523390 | G22: https://api.openalex.org/works/doi:10.1080/10494820.2025.2523390 | H22: https://api.openalex.org/works/doi:10.1080/10494820.2025.2523390 | I22: DOI | J22: Среден | K22: Записът е без том и книжка, само страници — непълен по IEEE. | L22: =COUNTIF('Ниво 2 Твърдения'!$C$2:$C$65,"*["&A22&"]*") | M22: Потвърдено | N22: Interactive Learning Environments, т. 34, кн. 3, с. 1435–1451, 2025 || НЯМА ДОСТЪП. ПРЕПОРЪКА: отпада. Ред 15 се пренасочва към [29] Quality Matters, който вече е потвърден (8 общи и 44 конкретни стандарта) и е точно „проверими насоки за дизайн и оценяване“. Ред 54 остава на Mayer 2021. | O22: ДЕЙСТВИЕ: добави том и книжка — записът беше непълен. || НАНЕСЕНО В НИП 28.08: добави vol. 34, no. 3. | P22: Claude (авт.) | Q22: 28.08.2026
A23: 22 | B23: 24 | C23: IEEE Standard for Learning Object Metadata | D23: Стандарт | E23: 2020 | F23: IEEE Std 1484.12.1-2020 | G23: https://ieeexplore.ieee.org/document/9262118/ | H23: https://ieeexplore.ieee.org/document/9262118/ | I23: IEEE SA; проверка на броя категории в ревизията от 2020 г. | J23: Критичен | K23: Твърдението за „девет категории“ произхожда от версията от 2002 г. Ревизията от 2020 г. има променена структура — ред 6 може да е верен за грешното издание. | L23: =COUNTIF('Ниво 2 Твърдения'!$C$2:$C$65,"*["&A23&"]*") | M23: Потвърдено | N23: IEEE Std 1484.12.1-2020 || НЯМА ДОСТЪП. ПРЕПОРЪКА: твърдението за деветте категории и четирите признака на Educational категорията не бива да стои без прочетен стандарт. Или се търси свободен източник, който описва схемата, или изречението се свежда до съществуването на международен стандарт за метаданни без изброяване на съдържанието му. || РЕШЕНО: съдържанието е потвърдено през свободното ръководство на 1EdTech/IMS за LOM v1.3. Записът трябва да сочи версията, която наистина е проверена. | O23: ОТМЕНЯМ по-ранното предупреждение: деветте категории от първо ниво важат и за ревизията от 2020 г. Остава да се провери съдържанието на Educational категорията (Ниво 2, ред 6). | P23: Claude (авт.) | Q23: 28.08.2026
A24: 23 | B24: 25 | C24: J. Biggs, C. Tang, G. Kennedy — Teaching for Quality Learning at University | D24: Книга | E24: 2022 | F24: 5-о изд., Open University Press | G24: https://www.mheducation.co.uk/teaching-for-quality-learning-at-university-5e-9780335250820-emea-group | H24: https://www.mheducation.co.uk/teaching-for-quality-learning-at-university-5e-9780335250820-emea-group | I24: Каталог на издателя/ISBN | J24: Среден | K24: Провери годината, изданието и състава на авторите за 5-о изд. | L24: =COUNTIF('Ниво 2 Твърдения'!$C$2:$C$65,"*["&A24&"]*") | M24: Потвърдено | N24: ISBN 9780335250820, McGraw Hill / Open University Press || НЯМА ДОСТЪП. ПРЕПОРЪКА: замяна с първоизточника на конструктивното съгласуване — Biggs, J. (1996). „Enhancing teaching through constructive alignment.“ Higher Education, 32(3), 347–364. Статия, не учебник, намира се далеч по-лесно. || ПРОВЕРЕН СВАЛЕНИЯТ ФАЙЛ: Enhancing_Teaching_Through_Constructive_Alignment.pdf е ПРЕЗЕНТАЦИЯ на PowerPoint от 2009 г. („Slide 1“, Acrobat PDFMaker for PowerPoint), 2332 думи слайдов текст, без резюме и без списък с литература. НЕ Е годна за цитиране в научен труд. Търси се статията Biggs (1996), Higher Education, 32(3), 347–364. || РЕШЕНО: свален е правилният файл Biggs1996_Article_EnhancingTeachingThroughConstr.pdf, Higher Education 32: 347–364. Учебникът от 2022 г. отпада. | O24: 5-о изд., Biggs, Tang, Kennedy. Годината 2022 да се сверя в каталога на издателя при финалната редакция. | P24: Claude (авт.) | Q24: 28.08.2026
A25: 24 | B25: 26 | C25: J. Sweller, J. van Merriënboer, F. Paas — Cognitive architecture… 20 years later | D25: Списание | E25: 2019 | F25: doi: 10.1007/s10648-019-09465-5 | G25: https://api.openalex.org/works/doi:10.1007/s10648-019-09465-5 | H25: https://api.openalex.org/works/doi:10.1007/s10648-019-09465-5 | I25: DOI | J25: Висок | K25: В тази статия авторите ревизират схващането за „полезно натоварване“ — формулировката в ред 11 трябва да съвпадне с ревизираната. | L25: =COUNTIF('Ниво 2 Твърдения'!$C$2:$C$65,"*["&A25&"]*") | M25: Потвърдено | N25: Educational Psychology Review, т. 31, кн. 2, с. 261–292, 2019 | O25: Точно съвпадение. | P25: Claude (авт.) | Q25: 28.08.2026
A26: 25 | B26: 27 | C26: L. Huang et al. — A survey on hallucination in LLMs | D26: Списание | E26: 2025 | F26: doi: 10.1145/3703155 | G26: https://arxiv.org/abs/2311.05232 | H26: https://arxiv.org/abs/2311.05232 | I26: DOI | J26: Среден | K26: Терминологична точност — „фактологични“ vs „faithfulness“ халюцинации (ред 22). | L26: =COUNTIF('Ниво 2 Твърдения'!$C$2:$C$65,"*["&A26&"]*") | M26: Потвърдено | N26: ACM TOIS, т. 43, кн. 2, с. 1–55 | O26: Онлайн 2024, книжка 2025 — годината 2025 в записа е защитима. | P26: Claude (авт.) | Q26: 28.08.2026
A27: 26 | B27: 28 | C27: L. Zheng et al. — Judging LLM-as-a-judge with MT-Bench and Chatbot Arena | D27: Конференция | E27: 2023 | F27: NeurIPS 2023 D&B; arXiv:2306.05685 | G27: https://arxiv.org/html/2306.05685v4 | H27: https://arxiv.org/html/2306.05685v4 | I27: arXiv | J27: Критичен | K27: Носи три процента (над 80, ~85, ~81), които се появяват два пъти в текста (редове 57 и 63) и трябва да съвпадат помежду си. | L27: =COUNTIF('Ниво 2 Твърдения'!$C$2:$C$65,"*["&A27&"]*") | M27: Потвърдено | N27: arXiv:2306.05685, NeurIPS 2023 D&B | O27: 13 автора, първи Lianmin Zheng — точно. | P27: Claude (авт.) | Q27: 28.08.2026
A28: 27 | B28: 29 | C28: M. D. Merrill — First principles of instruction | D28: Списание | E28: 2002 | F28: doi: 10.1007/BF02505024; т. 50, кн. 3, с. 43–59 | G28: https://api.openalex.org/works/doi:10.1007/bf02505024 | H28: https://api.openalex.org/works/doi:10.1007/bf02505024 | I28: DOI | J28: Висок | K28: Локаторът „с. 44–45“ не е проверим — няма достъп до пълния текст. 31.08.2026: локаторът е премахнат от текста; цитира се цялата статия (с. 43–59), която изцяло е посветена на петте принципа. | L28: =COUNTIF('Ниво 2 Твърдения'!$C$2:$C$65,"*["&A28&"]*") | M28: Потвърдено (ниво на статия) | N28: ETR&D, т. 50, кн. 3, с. 43–59, 2002 | O28: Точно съвпадение. Локаторът с. 44–45 остава за Ниво 2. | P28: Claude (авт.) | Q28: 28.08.2026
A29: 28 | B29: 31 | C29: O. Zawacki-Richter et al. — Systematic review of AI in higher education | D29: Списание | E29: 2019 | F29: doi: 10.1186/s41239-019-0171-0 | G29: https://link.springer.com/article/10.1186/s41239-019-0171-0 | H29: https://link.springer.com/article/10.1186/s41239-019-0171-0 | I29: DOI; отворен достъп | J29: Среден | K29: Периодът 2007–2018 и изводът за участието на педагози (ред 35). | L29: =COUNTIF('Ниво 2 Твърдения'!$C$2:$C$65,"*["&A29&"]*") | M29: Потвърдено | N29: IJETHE, т. 16, чл. 39, 2019 | O29: Четиримата автори съвпадат. Периодът 2007–2018 е потвърден (146 от 2656 публикации). | P29: Claude (авт.) | Q29: 28.08.2026
A30: 29 | B30: 32 | C30: Quality Matters — QM Higher Education Rubric, 7-о изд. | D30: Рубрика/стандарт | E30: 2023 | F30: qualitymatters.org | G30: https://educationaldevelopment.uams.edu/qualitymatters/qm-rubric | H30: https://educationaldevelopment.uams.edu/qualitymatters/qm-rubric | I30: Сайт на QM; официално описание на 7-о издание | J30: Критичен | K30: Числата „8 общи и 44 конкретни стандарта“ се менят между изданията (в 6-о изд. са 42) — ред 55. | L30: =COUNTIF('Ниво 2 Твърдения'!$C$2:$C$65,"*["&A30&"]*") | M30: Потвърдено | N30: QM HE Rubric, 7-о изд. | O30: Потвърдено: 8 общи и 44 конкретни ревизионни стандарта. Виж ред 55. | P30: Claude (авт.) | Q30: 28.08.2026
A31: 30 | B31: ОТПАДА | C31: R. C. Clark, R. E. Mayer — e-Learning and the Science of Instruction | D31: Книга | E31: 2024 | F31: 5-о изд., Wiley | G31: https://www.harvard.com/book/9781394177370 | H31: https://www.harvard.com/book/9781394177370 | I31: Каталог на Wiley; съдържание на изданието | J31: Критичен | K31: Втори по натовареност източник — 5 твърдения с локатори по глави (1, 4, 9, 12, 13, 21). Провери и годината на 5-о изд., и че номерата на главите отговарят на това издание. | L31: =COUNTIF('Ниво 2 Твърдения'!$C$2:$C$65,"*["&A31&"]*") | M31: Не се потвърждава | N31: Wiley, 5-о изд., ISBN 9781394177370 — 12.12.2023 г. || ПРОВЕРЕНА ЗАМЯНА (отхвърлена): scirp.org/pdf/psych_2023051914322531.pdf се оказва „Online Learning: A Cognitive Tool for Learning…“, A. Fenteng, сп. Psychology (SCIRP), 2023, doi 10.4236/psych.2023.145036. Друга тема, друг автор, не съдържа принципите на мултимедийното учене. НЕ Е годна замяна на Clark & Mayer. | O31: ГРЕШКА В ЗАПИСА: 5-о издание е публикувано на 12 декември 2023 г., не 2024. ДЕЙСТВИЕ: поправи годината на 2023 във всички препратки. || НАНЕСЕНО В НИП 28.08: годината става 2023. | P31: Claude (авт.) | Q31: 28.08.2026
A32: 31 | B32: 34 | C32: Регламент (ЕС) 2024/1689 (Акт за изкуствения интелект) | D32: Правен акт | E32: 2024 | F32: OJ L, 2024/1689, 12.7.2024 | G32: https://eur-lex.europa.eu/eli/reg/2024/1689/oj | H32: https://eur-lex.europa.eu/eli/reg/2024/1689/oj | I32: EUR-Lex | J32: Висок | K32: Твърдението за прозрачност при генерирано съдържание трябва да сочи конкретен член (чл. 50) — ред 50. | L32: =COUNTIF('Ниво 2 Твърдения'!$C$2:$C$65,"*["&A32&"]*") | M32: Потвърдено | N32: Регламент (ЕС) 2024/1689, OJ L 2024/1689, 12.7.2024 | O32: Приет 13.06.2024 — съвпада. Членът за прозрачност (чл. 50) да се посочи в текста (Ниво 2, ред 50). | P32: Claude (авт.) | Q32: 28.08.2026
A33: 32 | B33: 35 | C33: S. G. Ramezani, Z. S. Mostafavi — скала за акредитационни стандарти | D33: Списание | E33: 2025 | F33: doi: 10.1007/s10639-025-13587-5 | G33: https://api.openalex.org/works/doi:10.1007/s10639-025-13587-5 | H33: https://api.openalex.org/works/doi:10.1007/s10639-025-13587-5 | I33: DOI | J33: Нисък | K33: Стандартен запис. | L33: =COUNTIF('Ниво 2 Твърдения'!$C$2:$C$65,"*["&A33&"]*") | M33: Потвърдено | N33: Education and Information Technologies, т. 30, кн. 15, с. 21139–21187, 2025 | O33: Точно съвпадение. | P33: Claude (авт.) | Q33: 28.08.2026
A34: 33 | B34: 36 | C34: S. J. Warren et al. — Enhancing quality assurance through AI integration | D34: Списание | E34: 2026 | F34: Quality Assurance in Education, т. 34, кн. 2, с. 205–222 | G34: https://www.emerald.com/qae/article/34/2/205/1302250/Enhancing-quality-assurance-through-strategic | H34: https://www.emerald.com/qae/article/34/2/205/1302250/Enhancing-quality-assurance-through-strategic | I34: Сайт на Emerald; търсене по заглавие | J34: Висок | K34: Единственият запис в списъка на списание без DOI, при това с година 2026. Потвърди съществуването и допълни DOI. | L34: =COUNTIF('Ниво 2 Твърдения'!$C$2:$C$65,"*["&A34&"]*") | M34: Потвърдено | N34: QAE, т. 34, кн. 2, с. 205–222, 2026 | O34: Съществува. Автори S. J. Warren, E. Boston Vogt, B. Tincher, J. Yang. DOI: 10.1108/QAE-09-2024-0183 — ДЕЙСТВИЕ: добави го, това беше единственият запис на списание без DOI. || НАНЕСЕНО В НИП 28.08: добави doi: 10.1108/QAE-09-2024-0183. | P34: Claude (авт.) | Q34: 28.08.2026
A35: 34 | B35: 37 | C35: UNESCO — Recommendation on Open Educational Resources | D35: Препоръка (ЮНЕСКО) | E35: 2019 | F35: unesdoc.unesco.org/ark:/48223/pf0000383205 | G35: https://unesdoc.unesco.org/ark:/48223/pf0000383205 | H35: https://unesdoc.unesco.org/ark:/48223/pf0000383205 | I35: UNESDOC | J35: Нисък | K35: Стабилен източник. | L35: =COUNTIF('Ниво 2 Твърдения'!$C$2:$C$65,"*["&A35&"]*") | M35: Потвърдено | N35: UNESCO, 2019 | O35: Документът съществува. Самата ark-връзка да се отвори при финалната редакция — страницата се зарежда динамично и не се провери автоматично. | P35: Claude (авт.) | Q35: 28.08.2026
A36: 35 | B36: ОТПАДА | C36: X. Chen, Z. Hu, C. Wang — Empowering education development through AIGC | D36: Списание | E36: 2024 | F36: doi: 10.1007/s10639-024-12549-7 | G36: https://link.springer.com/content/pdf/10.1007/s10639-024-12549-7.pdf | H36: https://link.springer.com/content/pdf/10.1007/s10639-024-12549-7.pdf | I36: DOI | J36: Висок | K36: Най-често използваният чужд източник след [16] — 6 твърдения, част от които изглеждат като авторски синтез (редове 8, 23). | L36: =COUNTIF('Ниво 2 Твърдения'!$C$2:$C$65,"*["&A36&"]*") | M36: Потвърдено | N36: Education and Information Technologies, т. 29, кн. 13, с. 17485–17537, 2024 || НЯМА ДОСТЪП до пълния текст. ПРЕПОРЪКА: ред 19 се пренасочва към Wang и кол. 2024 (ESWA), който е свален и проверен; ред 37 вече е там; ред 45 се пренасочва към Wu, Wang и Wen 2026 (Acta Psychologica 266, 106874), който документира „excessive dependence on AI outputs“. Остава да носи само ред 16 (понятието AIGC) — или отпада изцяло. || ОТПАДА ИЗЦЯЛО. И четирите му места са прехвърлени към Bahroun и кол. 2023, Sustainability 15(17), 12983 — библиометричен и съдържателен преглед на генеративния ИИ в образованието, свободен достъп. Wang и кол. 2024 (ESWA) НЕ ставаше: „developments, such as generative AI, are absent from our sample articles“. | O36: X. Chen, Z. Hu, C. Wang — точно. | P36: Claude (авт.) | Q36: 28.08.2026
A37: 36 | B37: 41 | C37: Z. Liu et al. — COGENT | D37: Работилница (BEA 2025) | E37: 2025 | F37: Proc. BEA 2025 | G37: https://aclanthology.org/2025.bea-1.10/ | H37: https://aclanthology.org/2025.bea-1.10/ | I37: ACL Anthology | J37: Нисък | K37: Стандартен запис. | L37: =COUNTIF('Ниво 2 Твърдения'!$C$2:$C$65,"*["&A37&"]*") | M37: Потвърдено | N37: aclanthology.org/2025.bea-1.10, с. 129–143 | O37: Z. Liu, S. X. Yin, D. H.-L. Goh, N. F. Chen. DOI: 10.18653/v1/2025.bea-1.10. ДЕЙСТВИЕ: добави страници и DOI. || НАНЕСЕНО В НИП 28.08: добави pp. 129–143 и doi: 10.18653/v1/2025.bea-1.10. | P37: Claude (авт.) | Q37: 28.08.2026

Sheet Ниво 1 — всички 53
A1: № (текущ) | B1: Библиографски запис | C1: Тип | D1: Как е проверен | E1: Статус | F1: Линк / DOI | G1: Извадка или данни от източника | H1: Бележка | I1: Брой цитирания в текста | J1: Предишен ред | K1: Дата
A2: 1 | B2: А. Захариев, „Изкуственият интелект в образователната и научна степен „доктор“: дигитализация, регулация и кредитна акселерация“, в Сб. докл. Четвърта научно-практическа конференция с международно участие „Дигитална трансформация на образованието – проблеми и решения“, Русе, България, 2026, с. 15–23. | C2: Доклад в сборник (BG) | D2: Сборник на конференцията (PDF/ISBN); при липса — контакт с организатора или автора | E2: Потвърдено | F2: https://www.conf-dte.bg/docs/2026/p-2.pdf | G2: 2026_p-2.pdf, печ. стр. 15–23 | H2: Заглавие, автор (Андрей Захариев) и страници съвпадат. | I2: 2 | J2: Ниво 1 Източници!ред 2 | K2: 28.08.2026
A3: 2 | B3: Д. Димитранов и Г. Димитров, „Изкуственият интелект като инструмент за автоматизирано създаване на бази данни от тестови въпроси“, в Сб. докл. Четвърта научно-практическа конференция с международно участие „Дигитална трансформация на образованието – проблеми и решения“, Русе, България, 2026, с. 576–580. | C3: Доклад в сборник (BG) | D3: Сборник; проверка на числата 656 000 знака / 553 въпроса | E3: Потвърдено | F3: https://www.conf-dte.bg/docs/2026/p-100.pdf | G3: 2026_p-100.pdf, печ. стр. 576–580 | H3: Дилян Димитранов, Георги Димитров — съвпада. | I3: 6 | J3: Ниво 1 Източници!ред 3 | K3: 28.08.2026
A4: 3 | B4: Е. Даскалова, О. Попова, С. Стефанов, М. Пенчева и В. Стефанова, „Концептуален дизайн за базирана на изкуствен интелект платформа за обучение на студенти по дентална анатомия“, в Сб. докл. Четвърта научно-практическа конференция с международно участие „Дигитална трансформация на образованието – проблеми и решения“, Русе, България, 2026, с. 554–558. | C4: Доклад в сборник (BG) | D4: Сборник; проверка на списъка от петима автори | E4: Потвърдено | F4: https://www.conf-dte.bg/docs/2026/p-96.pdf | G4: 2026_p-96.pdf, печ. стр. 554–558 | H4: Петимата автори съвпадат, вкл. Весела Стефанова. | I4: 1 | J4: Ниво 1 Източници!ред 4 | K4: 28.08.2026
A5: 4 | B5: М. Дамесова, „Овладяване на сложни концепции чрез генеративен изкуствен интелект и дигитален storytelling“, в Сб. докл. Четвърта научно-практическа конференция с международно участие „Дигитална трансформация на образованието – проблеми и решения“, Русе, България, 2026, с. 717–721. | C5: Доклад в сборник (BG) | D5: Сборник | E5: Потвърдено | F5: https://www.conf-dte.bg/docs/2026/p-124.pdf | G5: 2026_p-124.pdf, печ. стр. 717–721 | H5: Милена Дамесова — съвпада. | I5: 1 | J5: Ниво 1 Източници!ред 5 | K5: 28.08.2026
A6: 5 | B6: М. Левунлиева, „ИИ в образованието – перспективата на педагога“, в Сб. докл. Четвърта научно-практическа конференция с международно участие „Дигитална трансформация на образованието – проблеми и решения“, Русе, България, 2026, с. 605–610. | C6: Доклад в сборник (BG) | D6: Сборник; проверка на извадката от 68 специалисти и на „трите оценъчни оси“ | E6: Потвърдено | F6: https://www.conf-dte.bg/docs/2026/p-106.pdf | G6: 2026_p-106.pdf, печ. стр. 605–610 | H6: Милена Левунлиева — съвпада. | I6: 1 | J6: Ниво 1 Източници!ред 6 | K6: 28.08.2026
A7: 6 | B7: М. Маркова, „Изкуственият интелект в помощ на ускореното учене: практически инструменти за преподаватели“, в Сб. докл. Четвърта научно-практическа конференция с международно участие „Дигитална трансформация на образованието – проблеми и решения“, Русе, България, 2026, с. 541–546. | C7: Доклад в сборник (BG) | D7: Сборник; проверка на диапазона 75–90 % | E7: Потвърдено | F7: https://www.conf-dte.bg/docs/2026/p-94.pdf | G7: 2026_p-94.pdf, печ. стр. 541–546 | H7: Мая Маркова — записът е верен. ВНИМАНИЕ: твърдението в ред 31 на Ниво 2 не се потвърждава. | I7: 2 | J7: Ниво 1 Източници!ред 7 | K7: 28.08.2026
A8: 7 | B8: С. Гафтанджиева и Р. Донева, „Генеративен изкуствен интелект в образованието: проблеми и решения“, Педагогика, т. 97, кн. 9, с. 1284–1297, 2025, doi: 10.53656/ped2025-9.04. | C8: Списание (BG) | D8: DOI резолвер; проверка на вторично цитираното число „една шеста“ | E8: Потвърдено | F8: https://journals.azbuki.bg/pedagogy/generativen-izkustven-intelekt-v-obrazovanieto-problemi-i-reseniya/view | G8: печ. стр. 1284–1297; doi 10.53656/ped2025-9.04 | H8: Педагогика, т. 97, кн. 9, 2025 — съвпада. | I8: 2 | J8: Ниво 1 Източници!ред 8 | K8: 28.08.2026
A9: 8 | B9: Ц. Василев, „Използване на изкуствен интелект в обучението – гледна точка на студент и преподавател“, в Сб. докл. Четвърта научно-практическа конференция с международно участие „Дигитална трансформация на образованието – проблеми и решения“, Русе, България, 2026, с. 24–32. | C9: Доклад в сборник (BG) | D9: Сборник; проверка дали докладът наистина прави преглед на ~130 източника | E9: Потвърдено | F9: https://www.conf-dte.bg/docs/2026/p-3.pdf | G9: 2026_p-3.pdf, печ. стр. 24–32 | H9: Цветомир Василев — съвпада. | I9: 2 | J9: Ниво 1 Източници!ред 9 | K9: 28.08.2026
A10: 9 | B10: Ц. Дуцова, „Някои аспекти на приложение на изкуствения интелект в образованието“, в Сб. докл. Трета национална научно-практическа конференция „Дигитална трансформация на образованието – проблеми и решения“, Русе, България, 2025, с. 472–478. | C10: Доклад в сборник (BG) | D10: Сборник | E10: Потвърдено | F10: https://www.conf-dte.bg/docs/2025/p-84.pdf | G10: 2025_p-84.pdf, печ. стр. 472–478 | H10: Цветанка Дуцова, Трета конференция 2025 — съвпада. | I10: 1 | J10: Ниво 1 Източници!ред 10 | K10: 28.08.2026
A11: 10 | B11: A. S. Doğruöz et al., "Challenges and recommendations for LLMs-as-a-judge in multilingual settings and low-resource languages," 2026, arXiv:2607.02235. | C11: Препринт | D11: arxiv.org/abs/2607.02235 — първо съществуване, после авторство | E11: Потвърдено | F11: https://arxiv.org/html/2607.02235v1 | G11: arXiv:2607.02235 — съществува | H11: Заглавието съвпада. Автори: A. S. Doğruöz, X. Liao, V. Blaschke, J. Prange, S. Li, D. I. Adelani и др. ДЕЙСТВИЕ: добави авторите — запис без автор е формално некоректен по IEEE. Числата 650/33 се потвърждават. || НАНЕСЕНО В НИП 28.08: добави „A. S. Doğruöz et al.“ пред заглавието. | I11: 3 | J11: Ниво 1 Източници!ред 11 | K11: 28.08.2026
A12: 11 | B12: A. Sangrà, D. Vlachopoulos, and N. Cabrera, "Building an inclusive definition of e-learning: An approach to the conceptual framework," The International Review of Research in Open and Distributed Learning, vol. 13, no. 2, pp. 145–159, 2012, doi: 10.19173/irrodl.v13i2.1161. | C12: Списание (IRRODL) | D12: PDF в downloaded_pdfs + DOI | E12: Потвърдено | F12: https://doi.org/10.19173/irrodl.v13i2.1161 | G12: „Building an Inclusive Definition of E-Learning: An Approach to the Conceptual Framework“ — Albert Sangrà, Dimitrios Vlachopoulos, Nati Cabrera, Universitat Oberta de Catalunya | H12: aupress-admin,+Sangra2.pdf — заглавие и автори съвпадат дословно с записа. | I12: 2 | J12: НОВ РЕД — липсваше | K12: 31.08.2026
A13: 12 | B13: C. Redecker, European Framework for the Digital Competence of Educators: DigCompEdu, Y. Punie, Ed. Luxembourg: Publications Office of the European Union, 2017, JRC107466. | C13: Рамков документ (ЕС) | D13: Свободно достъпен PDF на JRC | E13: Потвърдено | F13: https://joint-research-centre.ec.europa.eu/digcompedu_en | G13: JRC107466, Publications Office of the EU, 2017 | H13: Redecker, ред. Punie — съвпада. | I13: 2 | J13: Ниво 1 Източници!ред 13 | K13: 28.08.2026
... A54: 53 | B54: Quality Matters, QM Higher Education Rubric, 7th ed. Annapolis, MD, USA: Quality Matters, 2023. [Online]. Available: https://www.qualitymatters.org/qa-resources/rubric-standards/higher-ed-rubric | C54: Рубрика/стандарт | D54: Сайт на QM; официално описание на 7-о издание | E54: Потвърдено | F54: https://educationaldevelopment.uams.edu/qualitymatters/qm-rubric | G54: QM HE Rubric, 7-о изд. | H54: Потвърдено: 8 общи и 44 конкретни ревизионни стандарта. Виж ред 55. | I54: 5 | J54: Ниво 1 Източници!ред 30 | K54: 28.08.2026

Sheet Списък 42
A1: Нов № | B1: Библиографски запис | C1: Стар № | D1: Бележка
A2: 1 | B2: А. Захариев, „Изкуственият интелект в образователната и научна степен „доктор“: дигитализация, регулация и кредитна акселерация“, в Сб. докл. Четвърта научно-практическа конференция с международно участие „Дигитална трансформация на образованието – проблеми и решения“, Русе, България, 2026, с. 15–23. | C2: 1
A3: 2 | B3: Д. Димитранов и Г. Димитров, „Изкуственият интелект като инструмент за автоматизирано създаване на бази данни от тестови въпроси“, в Сб. докл. Четвърта научно-практическа конференция с международно участие „Дигитална трансформация на образованието – проблеми и решения“, Русе, България, 2026, с. 576–580. | C3: 2
A4: 3 | B4: Е. Даскалова, О. Попова, С. Стефанов, М. Пенчева и В. Стефанова, „Концептуален дизайн за базирана на изкуствен интелект платформа за обучение на студенти по дентална анатомия“, в Сб. докл. Четвърта научно-практическа конференция с международно участие „Дигитална трансформация на образованието – проблеми и решения“, Русе, България, 2026, с. 554–558. | C4: 3
A5: 4 | B5: М. Дамесова, „Овладяване на сложни концепции чрез генеративен изкуствен интелект и дигитален storytelling“, в Сб. докл. Четвърта научно-практическа конференция с международно участие „Дигитална трансформация на образованието – проблеми и решения“, Русе, България, 2026, с. 717–721. | C5: 4
A6: 5 | B6: М. Левунлиева, „ИИ в образованието – перспективата на педагога“, в Сб. докл. Четвърта научно-практическа конференция с международно участие „Дигитална трансформация на образованието – проблеми и решения“, Русе, България, 2026, с. 605–610. | C6: 5
A7: 6 | B7: М. Маркова, „Изкуственият интелект в помощ на ускореното учене: практически инструменти за преподаватели“, в Сб. докл. Четвърта научно-практическа конференция с международно участие „Дигитална трансформация на образованието – проблеми и решения“, Русе, България, 2026, с. 541–546. | C7: 6
A8: 7 | B8: С. Гафтанджиева и Р. Донева, „Генеративен изкуствен интелект в образованието: проблеми и решения“, Педагогика, т. 97, кн. 9, с. 1284–1297, 2025, doi: 10.53656/ped2025-9.04. | C8: 7
A9: 8 | B9: Ц. Василев, „Използване на изкуствен интелект в обучението – гледна точка на студент и преподавател“, в Сб. докл. Четвърта научно-практическа конференция с международно участие „Дигитална трансформация на образованието – проблеми и решения“, Русе, България, 2026, с. 24–32. | C9: 8
A10: 9 | B10: Ц. Дуцова, „Някои аспекти на приложение на изкуствения интелект в образованието“, в Сб. докл. Трета национална научно-практическа конференция „Дигитална трансформация на образованието – проблеми и решения“, Русе, България, 2025, с. 472–478. | C10: 9
A11: 10 | B11: A. S. Doğruöz et al., "Challenges and recommendations for LLMs-as-a-judge in multilingual settings and low-resource languages," 2026, arXiv:2607.02235. | C11: 10
A12: 11 | B12: A. Sangrà, D. Vlachopoulos, and N. Cabrera, "Building an inclusive definition of e-learning: An approach to the conceptual framework," The International Review of Research in Open and Distributed Learning, vol. 13, no. 2, pp. 145–159, 2012, doi: 10.19173/irrodl.v13i2.1161. | D12: НОВ ИЗТОЧНИК
A13: 12 | B13: AI-Generated Content Best Practices, v1.0, 1EdTech Consortium, Lake Mary, FL, USA, 2025. [Online]. Available: https://www.imsglobal.org/resource/AI-Generated_Content_Best_Practices/v1p0 | D13: НОВ ИЗТОЧНИК
A14: 13 | B14: C. Redecker, European Framework for the Digital Competence of Educators: DigCompEdu, Y. Punie, Ed. Luxembourg: Publications Office of the European Union, 2017, JRC107466. | C14: 12
A15: 14 | B15: D. Li et al., "From generation to judgment: Opportunities and challenges of LLM-as-a-judge," in Proc. 2025 Conference on Empirical Methods in Natural Language Processing (EMNLP), 2025, pp. 2757–2791, doi: 10.18653/v1/2025.emnlp-main.138. | C15: 13
A16: 15 | B16: D. S. Chai, H. S. Kim, K. N. Kim, Y. Ha, S. S. H. Shin, and S. W. Yoon, "Generative artificial intelligence in instructional system design," Human Resource Development Review, vol. 24, no. 4, pp. 388–417, 2025, doi: 10.1177/15344843251320256. | C16: 14
A17: 16 | B17: E. Dickey and A. Bejarano, "GAIDE: A framework for using generative AI to assist in course content development," in Proc. 2024 IEEE Frontiers in Education Conference (FIE), 2024, pp. 1–9, doi: 10.1109/FIE61694.2024.10893132. | C17: 15
A18: 17 | B18: E. Kasneci et al., "ChatGPT for good? On opportunities and challenges of large language models for education," Learning and Individual Differences, vol. 103, Art. no. 102274, 2023, doi: 10.1016/j.lindif.2023.102274. | C18: 16
A19: 18 | B19: E. Staneviciene and G. Žekienė, "The use of multimedia in the teaching and learning process of higher education: A systematic review," Sustainability, vol. 17, no. 19, Art. no. 8859, 2025, doi: 10.3390/su17198859. | C19: 17
A20: 19 | B20: F. Miao and W. Holmes, Guidance for Generative AI in Education and Research. Paris, France: UNESCO, 2023. [Online]. Available: https://www.unesco.org/en/articles/guidance-generative-ai-education-and-research | C20: 18
A21: 20 | B21: G. W. Choi, S. H. Kim, D. Lee, and J. Moon, "Utilizing generative AI for instructional design: Exploring strengths, weaknesses, opportunities, and threats," TechTrends, vol. 68, no. 4, pp. 832–844, 2024, doi: 10.1007/s11528-024-00967-w. | C21: 19
A22: 21 | B22: H. Wu, Z. Wang, and X. Wen, "Examining interactive AI-supported learning environments: The mediating role of AI metacognition and the moderating role of cognitive flexibility," Acta Psychologica, vol. 266, Art. no. 106874, 2026. | D22: НОВ ИЗТОЧНИК
A23: 22 | B23: H. Yao, W. Xu, J. Turnau, N. Kellam, and H. Wei, "Instructional agents: Reducing teaching faculty workload through multi-agent instructional design," in Proc. EACL 2026, vol. 1, 2026, pp. 4087–4109, doi: 10.18653/v1/2026.eacl-long.191. | C23: 20
A24: 23 | B24: H. Zhang, S. Wang, T.-H. Chen, Y. Zou, and A. E. Hassan, "An empirical study of obsolete answers on Stack Overflow," IEEE Transactions on Software Engineering, vol. 47, no. 4, pp. 850–862, 2021, doi: 10.1109/TSE.2019.2906315. | C24: 11 | D24: НОВ ИЗТОЧНИК
A25: 24 | B25: IEEE Standard for Learning Object Metadata, IEEE Std 1484.12.1-2020, IEEE, New York, NY, USA, 2020. | C25: 22
A26: 25 | B26: J. Biggs, "Enhancing teaching through constructive alignment," Higher Education, vol. 32, no. 3, pp. 347–364, 1996, doi: 10.1007/BF00138871. | C26: 23 | D26: НОВ ИЗТОЧНИК
A27: 26 | B27: J. Sweller, J. J. G. van Merriënboer, and F. Paas, "Cognitive architecture and instructional design: 20 years later," Educational Psychology Review, vol. 31, no. 2, pp. 261–292, 2019, doi: 10.1007/s10648-019-09465-5. | C27: 24
A28: 27 | B28: L. Huang et al., "A survey on hallucination in large language models: Principles, taxonomy, challenges, and open questions," ACM Transactions on Information Systems, vol. 43, no. 2, pp. 1–55, 2025, doi: 10.1145/3703155. | C28: 25
A29: 28 | B29: L. Zheng et al., "Judging LLM-as-a-judge with MT-Bench and Chatbot Arena," in Advances in Neural Information Processing Systems 36 (NeurIPS 2023), Datasets and Benchmarks Track, 2023. [Online]. Available: https://arxiv.org/abs/2306.05685 | C29: 26
A30: 29 | B30: M. D. Merrill, "First principles of instruction," Educational Technology Research and Development, vol. 50, no. 3, pp. 43–59, 2002, doi: 10.1007/BF02505024. | C30: 27
A31: 30 | B31: N. F. Liu et al., "Lost in the middle: How language models use long contexts," Transactions of the Association for Computational Linguistics, vol. 12, pp. 157–173, 2024, doi: 10.1162/tacl_a_00638. | D31: НОВ ИЗТОЧНИК
A32: 31 | B32: O. Zawacki-Richter, V. I. Marín, M. Bond, and F. Gouverneur, "Systematic review of research on artificial intelligence applications in higher education — where are the educators?," International Journal of Educational Technology in Higher Education, vol. 16, Art. no. 39, 2019, doi: 10.1186/s41239-019-0171-0. | C32: 28
A33: 32 | B33: Quality Matters, QM Higher Education Rubric, 7th ed. Annapolis, MD, USA: Quality Matters, 2023. [Online]. Available: https://www.qualitymatters.org/qa-resources/rubric-standards/higher-ed-rubric | C33: 29
A34: 33 | B34: R. E. Mayer, "Evidence-based principles for how to design effective instructional videos," Journal of Applied Research in Memory and Cognition, vol. 10, no. 2, pp. 229–240, 2021, doi: 10.1016/j.jarmac.2021.03.007. | D34: НОВ ИЗТОЧНИК
A35: 34 | B35: Regulation (EU) 2024/1689 of the European Parliament and of the Council of 13 June 2024 laying down harmonised rules on artificial intelligence (Artificial Intelligence Act), OJ L, 2024/1689, 12.7.2024. [Online]. Available: https://eur-lex.europa.eu/eli/reg/2024/1689/oj | C35: 31
A36: 35 | B36: S. G. Ramezani and Z. S. Mostafavi, "Developing and validating a comprehensive scale for accreditation standards and quality assurance in e-learning institutions," Education and Information Technologies, vol. 30, no. 15, pp. 21139–21187, 2025, doi: 10.1007/s10639-025-13587-5. | C36: 32
A37: 36 | B37: S. J. Warren, E. Boston Vogt, B. Tincher, and J. Yang, "Enhancing quality assurance through strategic artificial intelligence integration: A framework for higher education digital transformation," Quality Assurance in Education, vol. 34, no. 2, pp. 205–222, 2026, doi: 10.1108/QAE-09-2024-0183. | C37: 33
A38: 37 | B38: UNESCO, Recommendation on Open Educational Resources (OER). Paris, France: UNESCO, 2019. [Online]. Available: https://unesdoc.unesco.org/ark:/48223/pf0000383205 | C38: 34
A39: 38 | B39: W. X. Zhao et al., "A survey of large language models," 2023, arXiv:2303.18223. | D39: НОВ ИЗТОЧНИК
A40: 39 | B40: Y. Gao et al., "Retrieval-augmented generation for large language models: A survey," 2023, arXiv:2312.10997. | D40: НОВ ИЗТОЧНИК
...

Sheet Ниво 2 Твърдения
A1: № | B1: Раздел | C1: Източник(ци) | D1: Източник(ци) — нови № | E1: Локатор в текста | F1: Твърдение (както е в документа) | G1: Тип на проверката | H1: Какво точно се потвърждава | I1: Приоритет | J1: Статус | K1: Намерено на (стр./раздел) | L1: Линк към проверения текст | M1: Извадка от източника (дословно) | N1: Бележка / действие | O1: Проверил | P1: Дата
A2: 1 | B2: 1.1 | C2: [30] | D2: заменен | E2: гл. 1 | F2: Clark и Mayer дефинират електронното обучение като обучение, доставяно чрез цифрово устройство, чието предназначение е да подпомага ученето, като изрично подчертават, че определящият признак не е технологията носител, а съчетанието от учебно съдържание и педагогически методи за неговото представяне [30, гл. 1]. | G2: Дефиниция | H2: Clark & Mayer, 5-о изд., гл. 1: дали дефиницията е такава и дали изрично се подчертава, че носителят не е определящият признак. | I2: Среден | J2: Потвърдено | K2: Sangrà, Vlachopoulos и Cabrera 2012, IRRODL 13(2), 145–159 — ЗАМЕСТИТЕЛ на [30, гл. 1] | L2: https://www.irrodl.org/index.php/irrodl/article/view/1161 | M2: Консенсусната дефиниция от Delphi проучването: „E-learning is an approach to teaching and learning, representing all or part of the educational model applied, that is based on the use of electronic media and devices as tools for improving access to training, communication and interaction and that facilitates the adoption of new ways of understanding and developing learning.“ Статията разграничава четири категории дефиниции: technology-driven, delivery-system-oriented, communication-oriented и educational-paradigm-oriented. | N2: ПОКРИВА СЕ ИЗЦЯЛО и по-добре от очакваното. Дефиницията определя е-обучението като ПОДХОД към преподаването и ученето, представящ приложения образователен модел, а електронните средства са „tools“. Това е точно тезата, че определящият признак е моделът, а не технологията — при това по консенсус на международен експертен панел, а не като едната страна на спора Кларк–Козма. Clark 1994 СТАВА ИЗЛИШЕН. | O2: Claude (авт.) | P2: 29.08.2026
A3: 2 | B3: 1.1 | C3: [12] | D3: [13] | E3: обл. 2 | F3: Значимостта на работата с дигитални ресурси за съвременния преподавател е призната и на рамково равнище: в европейската рамка за дигитална компетентност на преподавателите DigCompEdu подборът, създаването, модифицирането и управлението на дигитални ресурси са обособени като самостоятелна компетентностна област [12, обл. 2]. | G3: Рамков документ | H3: DigCompEdu: дали област 2 се нарича „Дигитални ресурси“ и обхваща подбор, създаване/модифициране и управление. | I3: Висок | J3: Потвърдено | K3: DigCompEdu, област 2 | L3: https://publications.jrc.ec.europa.eu/repository/bitstream/JRC107466/pdf_digcomedu_a4_final.pdf | M3: Област 2 „Digital Resources“ с подкомпетентности 2.1 Selecting digital resources, 2.2 Creating and modifying digital resources, 2.3 Managing, protecting and sharing digital resources. | N3: Потвърдено точно: подборът, създаването/модифицирането и управлението са обособени в самостоятелна област. | O3: Claude (авт.) | P3: 28.08.2026
A4: 3 | B4: 1.1 | C4: [30] | D4: заменен | E4: гл. 4 и 9 | F4: Изследванията върху мултимедийното учене показват, че комбинирането на словесна и визуална информация по правило води до по-добри учебни резултати от представянето само на текст, но единствено при спазване на установени принципи на дизайна — например съгласуваност между текст и изображение и изключване на несъщественото съдържание; в противен случай мултимедията може да затрудни, а не да подпомогне ученето [30, гл. 4 и 9]. | G4: Емпирично обобщение | H4: Гл. 4 и 9 на 5-о изд.: принцип на съгласуваност и изключване на несъщественото; дали източникът твърди и обратния ефект (мултимедия, която пречи). | I4: Висок | J4: Потвърдено | K4: Mayer 2021, JARMAC 10(2), 229–240 — ЗАМЕСТИТЕЛ на [30, гл. 4 и 9] | L4: https://www.sciencedirect.com/science/article/pii/S2211368121000231 | M4: „students learn better when extraneous comments and unneeded visual material are excluded (i.e., coherence principle)“; „Multimedia — Present words and graphics rather than words alone“; и за вредата: „Extraneous processing refers to cognitive processing during learning that does not serve the instructional objective of the lesson; it can be caused by poor instructional design, such as including extraneous graphics and text in the lesson.“ | N4: ПОКРИВА СЕ ИЗЦЯЛО от достъпен източник, включително частта „в противен случай мултимедията може да затрудни ученето“. Готово за замяна на локатора [30, гл. 4 и 9]. | O4: Claude (авт.) | P4: 29.08.2026
A5: 4 | B5: 1.1 | C5: [17] | D5: [18] | F5: Систематичните прегледи на използването на мултимедия във висшето образование потвърждават както широкото ѝ навлизане, така и зависимостта на ефектите от качеството на дидактическия дизайн [17]. | G5: Обобщение на преглед | H5: Дали прегледът наистина установява зависимост на ефектите от качеството на дидактическия дизайн, а не само разпространение. | I5: Среден | J5: Потвърдено | K5: [17] MDPI Sustainability 17(19):8859 | L5: https://www.mdpi.com/2071-1050/17/19/8859 | M5: „The integration of multimedia technologies into higher education is becoming increasingly widespread“; „multimedia tools enhance student engagement, motivation, and performance when integrated with clear pedagogical strategies“; „The effective implementation of multimedia tools requires a balance between technological innovation and pedagogical validity“. | N5: И двете части се потвърждават — навлизането и зависимостта от качеството на дизайна. | O5: Claude (авт.) | P5: 28.08.2026
A6: 5 | B6: 1.1 | C6: [34] | D6: [37] | F6: Значението на този режим е признато на международно равнище с препоръката на ЮНЕСКО за отворените образователни ресурси, която обвързва отвореното лицензиране с достъпа до качествено образование и с изграждането на капацитет за създаване, адаптиране и споделяне на такива ресурси [34]. | G6: Нормативен документ | H6: Дали Препоръката обвързва отвореното лицензиране с достъп до качествено образование И с изграждане на капацитет. | I6: Среден | J6: Потвърдено | K6: [34] UNESCO OER Recommendation, 2019 — свален PDF | L6: https://unesdoc.unesco.org/ark:/48223/pf0000383205 | M6: „Open Educational Resources (OER) can support quality education that is equitable, inclusive, open and participatory“; „Capacity building: developing the capacity of all key education stakeholders to create, access, re-use, re-purpose, adapt, and redistribute OER, as well as to use and apply open licenses“. | N6: Потвърдено по свалния от теб PDF. И двата елемента са налице — обвързването с качественото образование и изграждането на капацитет. | O6: Claude (авт.) | P6: 28.08.2026
A7: 6 | B7: 1.1 | C7: [22] | D7: [24] | F7: Международният стандарт за метаданни на учебни обекти определя структура от девет категории описателни характеристики, сред които образователната категория включва точно признаците, разгледани по-горе: вид на ресурса, равнище на интерактивност, целева аудитория и типично учебно време [22]. | G7: Точна структура | H7: Дали IEEE Std 1484.12.1-2020 определя девет категории и дали образователната включва точно четирите изброени признака. Внимание: „девет категории“ е от версията 2002 г. | I7: Висок | J7: Потвърдено | K7: 1EdTech/IMS Meta-data Best Practice Guide за IEEE 1484.12.1, v1.3 | L7: https://www.imsglobal.org/metadata/mdv1p3/imsmd_bestv1p3.html | M7: Деветте категории от първо ниво: General, Life Cycle, Meta-Metadata, Technical, Educational, Rights, Relation, Annotation, Classification. Категория 5 Educational съдържа Interactivity Type, Learning Resource Type, Interactivity Level, Intended End User Role, Context, Typical Age Range, Difficulty, Typical Learning Time. | N7: ПОТВЪРДЕНО чрез свободно достъпно авторитетно описание. И четирите признака, които изброяваш, се откриват: вид на ресурса (Learning Resource Type), равнище на интерактивност (Interactivity Level), целева аудитория (Intended End User Role / Typical Age Range) и типично учебно време (Typical Learning Time). ВНИМАНИЕ: ръководството описва версията от 2002 г. Или смени записа на 1484.12.1-2002, или цитирай ръководството отделно за съдържанието. | O7: Claude (авт.) | P7: 29.08.2026
